2020-05-12 10:05:26.478949: I tensorflow/stream_executor/platform/default/dso_loader.cc:44] Successfully opened dynamic library libcuda.so.1
2020-05-12 10:05:26.550343: E tensorflow/stream_executor/cuda/cuda_driver.cc:351] failed call to cuInit: CUDA_ERROR_NO_DEVICE: no CUDA-capable device is detected
2020-05-12 10:05:26.550409: I tensorflow/stream_executor/cuda/cuda_diagnostics.cc:169] retrieving CUDA diagnostic information for host: xenon6.fmi.ch
2020-05-12 10:05:26.550426: I tensorflow/stream_executor/cuda/cuda_diagnostics.cc:176] hostname: xenon6.fmi.ch
2020-05-12 10:05:26.550539: I tensorflow/stream_executor/cuda/cuda_diagnostics.cc:200] libcuda reported version is: 440.64.0
2020-05-12 10:05:26.550587: I tensorflow/stream_executor/cuda/cuda_diagnostics.cc:204] kernel reported version is: 440.64.0
2020-05-12 10:05:26.550600: I tensorflow/stream_executor/cuda/cuda_diagnostics.cc:310] kernel version seems to match DSO: 440.64.0
2020-05-12 10:05:26.550879: I tensorflow/core/platform/cpu_feature_guard.cc:142] Your CPU supports instructions that this TensorFlow binary was not compiled to use: SSE4.1 SSE4.2 AVX AVX2 AVX512F FMA
2020-05-12 10:05:26.568378: I tensorflow/core/platform/profile_utils/cpu_utils.cc:94] CPU Frequency: 2700000000 Hz
2020-05-12 10:05:26.578512: I tensorflow/compiler/xla/service/service.cc:168] XLA service 0x5643cd7faae0 initialized for platform Host (this does not guarantee that XLA will be used). Devices:
2020-05-12 10:05:26.578558: I tensorflow/compiler/xla/service/service.cc:176]   StreamExecutor device (0): Host, Default Version
252.0000000000005 188.0
96.00000000008592 252.0
408.0 128.0
396.0 132.0
108.00000023149215 4.0
Traceback (most recent call last):
  File "../evaluation/run_evaluation.py", line 39, in <module>
    main()
  File "../evaluation/run_evaluation.py", line 28, in main
    f1_score, l2_norm = predictor.evaluate()
  File "../evaluation/spots_predictor.py", line 80, in evaluate
    gauss_preds = util.gauss_evaluate(x, preds, self.cell_size, self.crop_size)
  File "../evaluation/util.py", line 125, in gauss_evaluate
    pred = gauss_single_image(images[i], masks[i], cell_size, crop_size)
  File "../evaluation/util.py", line 116, in gauss_single_image
    pred = get_prediction_matrix(prediction_coord, image.shape[0], cell_size, image.shape[1])
  File "../training/util_prepare.py", line 125, in get_prediction_matrix
    pred[i, j, 0] = 1
IndexError: index 128 is out of bounds for axis 0 with size 128
